Workbook

Sheet Comece aqui
A1: PLANO DE RECEITA
A2: MANUAL DE DONOS · de onde a venda vem, como ela acontece e onde colocar o próximo esforço
A4: Gestão de receita é conseguir olhar para a receita e saber de onde ela vem, onde mexer e como gerar mais. Enquanto o faturamento for um bolo só, você reage à receita. Quando cada fonte tem nome e número, você opera a receita.
A6: A PERGUNTA QUE GUIA TUDO: O QUE precisa ser feito, QUANTAS vezes, COMO e POR QUEM, para vendermos?
A8: OS 3 NÍVEIS DO PLANO DE RECEITA
A9: Nível | B9: Pergunta-chave | C9: O que você passa a saber | D9: O que isso destrava | E9: Onde está na planilha
A10: NÍVEL 1 Visibilidade | B10: De onde a venda vem? | C10: Quanto cada fonte de receita gera. | D10: Você para de olhar o faturamento como um bolo só e enxerga dinheiros diferentes. | E10: Aba 1 · colunas Receita e % da receita
A11: NÍVEL 2 Controle | B11: Como cada fonte vira venda? | C11: Quantas entradas viram proposta e quantas propostas viram venda, por fonte. | D11: Você enxerga o funil de cada fonte e acha o gargalo — o ponto exato onde a venda trava. | E11: Aba 1 · colunas Entradas, Propostas, Vendas e Conversões
A12: NÍVEL 3 Decisão | B12: Onde colocar o próximo esforço? | C12: Quanto de receita cada entrada gera, fonte por fonte. | D12: Você descobre que R$ 1 de um canal não vale o mesmo que R$ 1 de outro — e para de investir tempo no lugar errado. | E12: Aba 1 · coluna Receita por entrada
A14: COMO USAR ESSA PLANILHA — 6 PASSOS
A15: 1. Nomeie suas fontes | B15: Na aba «1. Plano de Receita», escreva todas as fontes de receita que JÁ existem hoje. Não invente nenhuma nova ainda.
A16: 2. Preencha o último mês fechado | B16: Para cada fonte: entradas, propostas, vendas e receita. Se você não mede alguma coisa, escreva sua melhor estimativa e marque para começar a contar. Aprender a contar vem antes de otimizar.
A17: 3. Leia o diagnóstico | B17: A própria aba 1 aponta sua maior fonte, seu melhor canal por entrada, seu maior gargalo de conversão e onde você gasta esforço sem retorno.
A18: 4. Simule a meta | B18: Na aba «2. Simulador de Meta», coloque a meta de receita e mexa nas entradas, conversões e ticket. A planilha mostra o gap e quantas entradas faltam no melhor canal para fechá-lo.
A19: 5. Projete o ano | B19: A aba «3. Projeção 12 meses» transforma o mês simulado em um plano de 12 meses, fonte por fonte.
A20: 6. Transforme em processo e cadência | B20: Na aba «5. Processos e Cadência», escreva o que precisa ser feito, quantas vezes, como e por quem — e marque o comitê de receita semanal na agenda. Plano sem cadência vira intenção.
A22: LEGENDA — o que você edita e o que a planilha calcula
A23: Texto azul, fundo amarelo | B23: Você preenche. É input seu.
A24: Texto preto | B24: Fórmula. Não mexa — a planilha calcula sozinha.
A25: Texto verde | B25: Veio de outra aba. Se mudar lá, muda aqui.
A27: REGRA DE OURO: você não gerencia o resultado, você gerencia as atividades e monitora os indicadores de direção — o resultado é consequência. Crescer é empilhar fontes que funcionam: acertou uma, mantenha; vá buscar a próxima; some forças, não troque apostas.
A29: Baseado no manual «Processo comercial: manual para destravar as vendas» — Manual de Donos, com Jonathan Souza.

Sheet 1. Plano de Receita
A1: 1. PLANO DE RECEITA — O RETRATO DE HOJE
A2: Níveis 1, 2 e 3 na mesma tabela: de onde vem, como acontece e quanto vale cada entrada
A4: Negócio: | G4: Período de referência: | I4: Último mês fechado
A5: Modelo de negócio:
A7: PREENCHA AS COLUNAS AMARELAS. O RESTO A PLANILHA CALCULA.
A8: Fonte de receita | B8: Entradas | C8: Propostas | D8: Vendas | E8: Receita (R$) | F8: Ticket médio | G8: Conv. entrada→proposta | H8: Conv. proposta→venda | I8: Conv. Entrada→Venda | J8: Receita por entrada | K8: % da receita
A9: Indicação (exemplo — apague e coloque as suas) | B9: 40 | C9: 20 | D9: 11 | E9: 80000 | F9: =IFERROR(E9/D9,"") -> 7272.7273 | G9: =IFERROR(C9/B9,"") -> 0.5 | H9: =IFERROR(D9/C9,"") -> 0.55 | I9: =IFERROR(D9/B9,"") -> 0.275 | J9: =IFERROR(E9/B9,"") -> 2000 | K9: =IFERROR(E9/$E$21,"") -> 1
F10: =IFERROR(E10/D10,"") | G10: =IFERROR(C10/B10,"") | H10: =IFERROR(D10/C10,"") | I10: =IFERROR(D10/B10,"") | J10: =IFERROR(E10/B10,"") | K10: =IFERROR(E10/$E$21,"") -> 0
F11: =IFERROR(E11/D11,"") | G11: =IFERROR(C11/B11,"") | H11: =IFERROR(D11/C11,"") | I11: =IFERROR(D11/B11,"") | J11: =IFERROR(E11/B11,"") | K11: =IFERROR(E11/$E$21,"") -> 0
F12: =IFERROR(E12/D12,"") | G12: =IFERROR(C12/B12,"") | H12: =IFERROR(D12/C12,"") | I12: =IFERROR(D12/B12,"") | J12: =IFERROR(E12/B12,"") | K12: =IFERROR(E12/$E$21,"") -> 0
F13: =IFERROR(E13/D13,"") | G13: =IFERROR(C13/B13,"") | H13: =IFERROR(D13/C13,"") | I13: =IFERROR(D13/B13,"") | J13: =IFERROR(E13/B13,"") | K13: =IFERROR(E13/$E$21,"") -> 0
F14: =IFERROR(E14/D14,"") | G14: =IFERROR(C14/B14,"") | H14: =IFERROR(D14/C14,"") | I14: =IFERROR(D14/B14,"") | J14: =IFERROR(E14/B14,"") | K14: =IFERROR(E14/$E$21,"") -> 0
F15: =IFERROR(E15/D15,"") | G15: =IFERROR(C15/B15,"") | H15: =IFERROR(D15/C15,"") | I15: =IFERROR(D15/B15,"") | J15: =IFERROR(E15/B15,"") | K15: =IFERROR(E15/$E$21,"") -> 0
F16: =IFERROR(E16/D16,"") | G16: =IFERROR(C16/B16,"") | H16: =IFERROR(D16/C16,"") | I16: =IFERROR(D16/B16,"") | J16: =IFERROR(E16/B16,"") | K16: =IFERROR(E16/$E$21,"") -> 0
F17: =IFERROR(E17/D17,"") | G17: =IFERROR(C17/B17,"") | H17: =IFERROR(D17/C17,"") | I17: =IFERROR(D17/B17,"") | J17: =IFERROR(E17/B17,"") | K17: =IFERROR(E17/$E$21,"") -> 0
F18: =IFERROR(E18/D18,"") | G18: =IFERROR(C18/B18,"") | H18: =IFERROR(D18/C18,"") | I18: =IFERROR(D18/B18,"") | J18: =IFERROR(E18/B18,"") | K18: =IFERROR(E18/$E$21,"") -> 0
F19: =IFERROR(E19/D19,"") | G19: =IFERROR(C19/B19,"") | H19: =IFERROR(D19/C19,"") | I19: =IFERROR(D19/B19,"") | J19: =IFERROR(E19/B19,"") | K19: =IFERROR(E19/$E$21,"") -> 0
F20: =IFERROR(E20/D20,"") | G20: =IFERROR(C20/B20,"") | H20: =IFERROR(D20/C20,"") | I20: =IFERROR(D20/B20,"") | J20: =IFERROR(E20/B20,"") | K20: =IFERROR(E20/$E$21,"") -> 0
A21: TOTAL | B21: =SUM(B9:B20) -> 40 | C21: =SUM(C9:C20) -> 20 | D21: =SUM(D9:D20) -> 11 | E21: =SUM(E9:E20) -> 80000 | F21: =IFERROR(E21/D21,"") -> 7272.7273 | G21: =IFERROR(C21/B21,"") -> 0.5 | H21: =IFERROR(D21/C21,"") -> 0.55 | I21: =IFERROR(D21/B21,"") -> 0.275 | J21: =IFERROR(E21/B21,"") -> 2000 | K21: =IFERROR(SUM(K9:K20),"") -> 1
A23: LEITURA AUTOMÁTICA DO SEU PLANO — o que esses números já estão te dizendo
A24: Sua maior fonte de receita | B24: =IFERROR(INDEX($A$9:$A$20,MATCH(MAX($E$9:$E$20),$E$9:$E$20,0)),"") -> Indicação (exemplo — apague e coloque as suas) | E24: =IFERROR(MAX($E$9:$E$20),"") -> 80000 | F24: É de onde o dinheiro vem hoje. Antes de buscar canal novo, garanta que essa fonte não vai cair.
A25: Sua entrada mais valiosa (maior receita por entrada) | B25: =IFERROR(INDEX($A$9:$A$20,MATCH(MAX($J$9:$J$20),$J$9:$J$20,0)),"") -> Indicação (exemplo — apague e coloque as suas) | E25: =IFERROR(MAX($J$9:$J$20),"") -> 2000 | F25: Se você tem 1 hora para vender, é aqui que ela rende mais. Pergunte-se: como eu gero MAIS entradas nesse canal?
A26: Sua entrada menos valiosa (menor receita por entrada) | B26: =IFERROR(INDEX($A$9:$A$20,MATCH(MIN($J$9:$J$20),$J$9:$J$20,0)),"") -> Indicação (exemplo — apague e coloque as suas) | E26: =IFERROR(MIN($J$9:$J$20),"") -> 2000 | F26: Não significa abandonar. Significa que aqui o jogo é volume e eficiência — e que uma melhora pequena por entrada vira muito dinheiro.
A27: Onde você gasta mais esforço (mais entradas) | B27: =IFERROR(INDEX($A$9:$A$20,MATCH(MAX($B$9:$B$20),$B$9:$B$20,0)),"") -> Indicação (exemplo — apague e coloque as suas) | E27: =IFERROR(MAX($B$9:$B$20),"") -> 40 | F27: Compare com a linha acima: se o maior esforço estiver na entrada menos valiosa, seu time está trabalhando no lugar errado.
A28: Seu maior gargalo (pior conversão entrada→venda) | B28: =IFERROR(INDEX($A$9:$A$20,MATCH(MIN($I$9:$I$20),$I$9:$I$20,0)),"") -> Indicação (exemplo — apague e coloque as suas) | E28: =IFERROR(MIN($I$9:$I$20),"") -> 0.275 | F28: É o ponto do funil onde a venda trava. Arrumar conversão é mais barato do que comprar mais entradas.
A30: COMO PREENCHER CADA COLUNA
A31: Fonte de receita | B31: Dê nome a cada origem de venda: carteira ativa, indicação, prospecção ativa, inbound, eventos, parcerias, canal indireto, fluxo de loja, WhatsApp, marketplace. Cada fonte é, na prática, um dinheiro diferente.
A32: Entradas | B32: Todo contato inicial do período: pessoa que entrou na loja, lead que preencheu formulário, orçamento pedido, visita agendada, DM respondida. Se você não sabe, comece contando — engenheiro de tráfego conta carro por carro antes de projetar a rua.
A33: Propostas | B33: O meio do caminho: proposta enviada, orçamento passado, atendimento com prova, cliente que pediu preço. Se o seu negócio não tem essa etapa, repita o número de vendas.
A34: Vendas | B34: Quantos negócios fecharam no período, vindos daquela fonte.
A35: Receita (R$) | B35: Quanto de receita aquela fonte gerou no período. A soma tem que bater com o seu faturamento total.

Sheet 2. Simulador de Meta
A1: 2. SIMULADOR DE META
A2: Mexa nas entradas, na conversão e no ticket. Veja a receita mudar e o gap até a meta fechar.
A4: META DE RECEITA DO PERÍODO: | D4: Receita de hoje (aba 1): | F4: ='1. Plano de Receita'!E21 -> 80000
A6: AS LINHAS COMEÇAM IGUAIS AO SEU RETRATO DE HOJE. SOBRESCREVA À VONTADE — É PARA ISSO QUE ELA SERVE.
A7: Fonte de receita | B7: Entradas planejadas | C7: Conv. entrada→venda | D7: Ticket médio (R$) | E7: Vendas projetadas | F7: Receita projetada (R$) | G7: Receita por entrada | H7: Receita hoje (R$) | I7: Variação (R$) | J7: Variação %
A8: =IF('1. Plano de Receita'!A9="","",'1. Plano de Receita'!A9) -> Indicação (exemplo — apague e coloque as suas) | B8: =IF('1. Plano de Receita'!B9="","",'1. Plano de Receita'!B9) -> 40 | C8: =IF('1. Plano de Receita'!I9="","",'1. Plano de Receita'!I9) -> 0.275 | D8: =IF('1. Plano de Receita'!F9="","",'1. Plano de Receita'!F9) -> 7272.7273 | E8: =IFERROR(B8*C8,"") -> 11 | F8: =IFERROR(E8*D8,0) -> 80000 | G8: =IFERROR(F8/B8,"") -> 2000 | H8: =IF('1. Plano de Receita'!E9="","",'1. Plano de Receita'!E9) -> 80000 | I8: =IFERROR(F8-H8,"") -> 0 | J8: =IFERROR(I8/H8,"") -> 0
A9: =IF('1. Plano de Receita'!A10="","",'1. Plano de Receita'!A10) | B9: =IF('1. Plano de Receita'!B10="","",'1. Plano de Receita'!B10) | C9: =IF('1. Plano de Receita'!I10="","",'1. Plano de Receita'!I10) | D9: =IF('1. Plano de Receita'!F10="","",'1. Plano de Receita'!F10) | E9: =IFERROR(B9*C9,"") | F9: =IFERROR(E9*D9,0) -> 0 | G9: =IFERROR(F9/B9,"") | H9: =IF('1. Plano de Receita'!E10="","",'1. Plano de Receita'!E10) | I9: =IFERROR(F9-H9,"") | J9: =IFERROR(I9/H9,"")
A10: =IF('1. Plano de Receita'!A11="","",'1. Plano de Receita'!A11) | B10: =IF('1. Plano de Receita'!B11="","",'1. Plano de Receita'!B11) | C10: =IF('1. Plano de Receita'!I11="","",'1. Plano de Receita'!I11) | D10: =IF('1. Plano de Receita'!F11="","",'1. Plano de Receita'!F11) | E10: =IFERROR(B10*C10,"") | F10: =IFERROR(E10*D10,0) -> 0 | G10: =IFERROR(F10/B10,"") | H10: =IF('1. Plano de Receita'!E11="","",'1. Plano de Receita'!E11) | I10: =IFERROR(F10-H10,"") | J10: =IFERROR(I10/H10,"")
A11: =IF('1. Plano de Receita'!A12="","",'1. Plano de Receita'!A12) | B11: =IF('1. Plano de Receita'!B12="","",'1. Plano de Receita'!B12) | C11: =IF('1. Plano de Receita'!I12="","",'1. Plano de Receita'!I12) | D11: =IF('1. Plano de Receita'!F12="","",'1. Plano de Receita'!F12) | E11: =IFERROR(B11*C11,"") | F11: =IFERROR(E11*D11,0) -> 0 | G11: =IFERROR(F11/B11,"") | H11: =IF('1. Plano de Receita'!E12="","",'1. Plano de Receita'!E12) | I11: =IFERROR(F11-H11,"") | J11: =IFERROR(I11/H11,"")
A12: =IF('1. Plano de Receita'!A13="","",'1. Plano de Receita'!A13) | B12: =IF('1. Plano de Receita'!B13="","",'1. Plano de Receita'!B13) | C12: =IF('1. Plano de Receita'!I13="","",'1. Plano de Receita'!I13) | D12: =IF('1. Plano de Receita'!F13="","",'1. Plano de Receita'!F13) | E12: =IFERROR(B12*C12,"") | F12: =IFERROR(E12*D12,0) -> 0 | G12: =IFERROR(F12/B12,"") | H12: =IF('1. Plano de Receita'!E13="","",'1. Plano de Receita'!E13) | I12: =IFERROR(F12-H12,"") | J12: =IFERROR(I12/H12,"")
A13: =IF('1. Plano de Receita'!A14="","",'1. Plano de Receita'!A14) | B13: =IF('1. Plano de Receita'!B14="","",'1. Plano de Receita'!B14) | C13: =IF('1. Plano de Receita'!I14="","",'1. Plano de Receita'!I14) | D13: =IF('1. Plano de Receita'!F14="","",'1. Plano de Receita'!F14) | E13: =IFERROR(B13*C13,"") | F13: =IFERROR(E13*D13,0) -> 0 | G13: =IFERROR(F13/B13,"") | H13: =IF('1. Plano de Receita'!E14="","",'1. Plano de Receita'!E14) | I13: =IFERROR(F13-H13,"") | J13: =IFERROR(I13/H13,"")
A14: =IF('1. Plano de Receita'!A15="","",'1. Plano de Receita'!A15) | B14: =IF('1. Plano de Receita'!B15="","",'1. Plano de Receita'!B15) | C14: =IF('1. Plano de Receita'!I15="","",'1. Plano de Receita'!I15) | D14: =IF('1. Plano de Receita'!F15="","",'1. Plano de Receita'!F15) | E14: =IFERROR(B14*C14,"") | F14: =IFERROR(E14*D14,0) -> 0 | G14: =IFERROR(F14/B14,"") | H14: =IF('1. Plano de Receita'!E15="","",'1. Plano de Receita'!E15) | I14: =IFERROR(F14-H14,"") | J14: =IFERROR(I14/H14,"")
A15: =IF('1. Plano de Receita'!A16="","",'1. Plano de Receita'!A16) | B15: =IF('1. Plano de Receita'!B16="","",'1. Plano de Receita'!B16) | C15: =IF('1. Plano de Receita'!I16="","",'1. Plano de Receita'!I16) | D15: =IF('1. Plano de Receita'!F16="","",'1. Plano de Receita'!F16) | E15: =IFERROR(B15*C15,"") | F15: =IFERROR(E15*D15,0) -> 0 | G15: =IFERROR(F15/B15,"") | H15: =IF('1. Plano de Receita'!E16="","",'1. Plano de Receita'!E16) | I15: =IFERROR(F15-H15,"") | J15: =IFERROR(I15/H15,"")
A16: =IF('1. Plano de Receita'!A17="","",'1. Plano de Receita'!A17) | B16: =IF('1. Plano de Receita'!B17="","",'1. Plano de Receita'!B17) | C16: =IF('1. Plano de Receita'!I17="","",'1. Plano de Receita'!I17) | D16: =IF('1. Plano de Receita'!F17="","",'1. Plano de Receita'!F17) | E16: =IFERROR(B16*C16,"") | F16: =IFERROR(E16*D16,0) -> 0 | G16: =IFERROR(F16/B16,"") | H16: =IF('1. Plano de Receita'!E17="","",'1. Plano de Receita'!E17) | I16: =IFERROR(F16-H16,"") | J16: =IFERROR(I16/H16,"")
A17: =IF('1. Plano de Receita'!A18="","",'1. Plano de Receita'!A18) | B17: =IF('1. Plano de Receita'!B18="","",'1. Plano de Receita'!B18) | C17: =IF('1. Plano de Receita'!I18="","",'1. Plano de Receita'!I18) | D17: =IF('1. Plano de Receita'!F18="","",'1. Plano de Receita'!F18) | E17: =IFERROR(B17*C17,"") | F17: =IFERROR(E17*D17,0) -> 0 | G17: =IFERROR(F17/B17,"") | H17: =IF('1. Plano de Receita'!E18="","",'1. Plano de Receita'!E18) | I17: =IFERROR(F17-H17,"") | J17: =IFERROR(I17/H17,"")
A18: =IF('1. Plano de Receita'!A19="","",'1. Plano de Receita'!A19) | B18: =IF('1. Plano de Receita'!B19="","",'1. Plano de Receita'!B19) | C18: =IF('1. Plano de Receita'!I19="","",'1. Plano de Receita'!I19) | D18: =IF('1. Plano de Receita'!F19="","",'1. Plano de Receita'!F19) | E18: =IFERROR(B18*C18,"") | F18: =IFERROR(E18*D18,0) -> 0 | G18: =IFERROR(F18/B18,"") | H18: =IF('1. Plano de Receita'!E19="","",'1. Plano de Receita'!E19) | I18: =IFERROR(F18-H18,"") | J18: =IFERROR(I18/H18,"")
A19: =IF('1. Plano de Receita'!A20="","",'1. Plano de Receita'!A20) | B19: =IF('1. Plano de Receita'!B20="","",'1. Plano de Receita'!B20) | C19: =IF('1. Plano de Receita'!I20="","",'1. Plano de Receita'!I20) | D19: =IF('1. Plano de Receita'!F20="","",'1. Plano de Receita'!F20) | E19: =IFERROR(B19*C19,"") | F19: =IFERROR(E19*D19,0) -> 0 | G19: =IFERROR(F19/B19,"") | H19: =IF('1. Plano de Receita'!E20="","",'1. Plano de Receita'!E20) | I19: =IFERROR(F19-H19,"") | J19: =IFERROR(I19/H19,"")
A20: Canal novo 1 (escreva aqui) | E20: =IFERROR(B20*C20,"") -> 0 | F20: =IFERROR(E20*D20,0) -> 0 | G20: =IFERROR(F20/B20,"") | H20: 0 | I20: =IFERROR(F20-H20,"") -> 0 | J20: =IFERROR(I20/H20,"")
A21: Canal novo 2 (escreva aqui) | E21: =IFERROR(B21*C21,"") -> 0 | F21: =IFERROR(E21*D21,0) -> 0 | G21: =IFERROR(F21/B21,"") | H21: 0 | I21: =IFERROR(F21-H21,"") -> 0 | J21: =IFERROR(I21/H21,"")
A22: Canal novo 3 (escreva aqui) | E22: =IFERROR(B22*C22,"") -> 0 | F22: =IFERROR(E22*D22,0) -> 0 | G22: =IFERROR(F22/B22,"") | H22: 0 | I22: =IFERROR(F22-H22,"") -> 0 | J22: =IFERROR(I22/H22,"")
A23: TOTAL PROJETADO | B23: =SUM(B8:B22) -> 40 | E23: =SUM(E8:E22) -> 11 | F23: =SUM(F8:F22) -> 80000 | G23: =IFERROR(F23/B23,"") -> 2000 | H23: =SUM(H8:H22) -> 80000 | I23: =SUM(I8:I22) -> 0 | J23: =IFERROR(I23/H23,"") -> 0
A25: RESULTADO DA SIMULAÇÃO
A26: Receita projetada | B26: =F23 -> 80000 | D26: Soma da simulação acima.
A27: Meta de receita | B27: =C4 -> 0 | D27: O número que você escreveu lá em cima.
A28: Gap até a meta | B28: =C4-F23 -> -80000 | D28: Positivo = ainda falta. Negativo ou zero = a simulação já bate a meta.
A29: Situação | B29: =IF(C4="","Coloque a meta lá em cima",IF(C4-F23<=0,"META BATIDA nessa simulação","AINDA FALTA — ajuste entradas, conversão ou ticket")) -> Coloque a meta lá em cima | D29: Leitura rápida.
A30: Melhor canal por receita/entrada nessa simulação | B30: =IFERROR(INDEX($A$8:$A$22,MATCH(MAX($G$8:$G$22),$G$8:$G$22,0)),"") -> Indicação (exemplo — apague e coloque as suas) | D30: É onde cada entrada nova rende mais.
A31: Receita por entrada desse canal | B31: =IFERROR(MAX($G$8:$G$22),"") -> 2000 | D31: Quanto entra de receita a cada contato inicial gerado nele.
A32: Entradas adicionais nesse canal para fechar o gap | B32: =IF(C4="","",IF(C4-F23<=0,0,IFERROR(ROUNDUP((C4-F23)/MAX($G$8:$G$22),0),""))) | D32: Essa é a decisão que o plano gera: quantas entradas a mais, no canal certo, fecham a conta.
A34: AS 3 ALAVANCAS QUE VOCÊ TEM — e o custo de cada uma
A35: 1. Mais entradas (volume) | B35: Gerar mais contatos iniciais no canal. É a alavanca mais óbvia e normalmente a mais cara: exige mais anúncio, mais prospecção, mais gente. Só puxe essa depois de olhar as outras duas.
A36: 2. Melhor conversão (funil) | B36: Transformar em venda o que já chegou. É a alavanca mais barata: a entrada já foi paga. Uma conversão de 16% para 18% no seu maior canal costuma valer mais do que um mês inteiro de anúncio novo.
A37: 3. Ticket maior (valor) | B37: Vender mais por venda: combo, item adicional, escopo maior, plano anual. Não custa entrada nenhuma — custa processo de oferta. «Você conhece nosso produto mais vendido?» é ticket, não é sorte.

Sheet 3. Projeção 12 meses
A1: 3. PROJEÇÃO 12 MESES
A2: O mês simulado virando plano de ano, fonte por fonte. Mês 1 = a simulação da aba 2.
A4: Crescimento padrão por mês: | C4: 0 | D4: Aplicado a todas as fontes. Você pode sobrescrever fonte a fonte na coluna B — nem todo canal cresce no mesmo ritmo.
A6: Fonte de receita | B6: Cresc./mês | C6: Mês 1 | D6: Mês 2 | E6: Mês 3 | F6: Mês 4 | G6: Mês 5 | H6: Mês 6 | I6: Mês 7 | J6: Mês 8 | K6: Mês 9 | L6: Mês 10 | M6: Mês 11 | N6: Mês 12 | O6: Total 12 meses
A7: =IF('2. Simulador de Meta'!A8="","",'2. Simulador de Meta'!A8) -> Indicação (exemplo — apague e coloque as suas) | B7: =$C$4 -> 0 | C7: ='2. Simulador de Meta'!F8 -> 80000 | D7: =C7*(1+$B7) -> 80000 | E7: =D7*(1+$B7) -> 80000 | F7: =E7*(1+$B7) -> 80000 | G7: =F7*(1+$B7) -> 80000 | H7: =G7*(1+$B7) -> 80000 | I7: =H7*(1+$B7) -> 80000 | J7: =I7*(1+$B7) -> 80000 | K7: =J7*(1+$B7) -> 80000 | ... N7: =M7*(1+$B7) -> 80000 | O7: =SUM(C7:N7) -> 960000
A8: =IF('2. Simulador de Meta'!A9="","",'2. Simulador de Meta'!A9) | B8: =$C$4 -> 0 | C8: ='2. Simulador de Meta'!F9 -> 0 | D8: =C8*(1+$B8) -> 0 | E8: =D8*(1+$B8) -> 0 | F8: =E8*(1+$B8) -> 0 | G8: =F8*(1+$B8) -> 0 | H8: =G8*(1+$B8) -> 0 | I8: =H8*(1+$B8) -> 0 | J8: =I8*(1+$B8) -> 0 | K8: =J8*(1+$B8) -> 0 | ... N8: =M8*(1+$B8) -> 0 | O8: =SUM(C8:N8) -> 0
A9: =IF('2. Simulador de Meta'!A10="","",'2. Simulador de Meta'!A10) | B9: =$C$4 -> 0 | C9: ='2. Simulador de Meta'!F10 -> 0 | D9: =C9*(1+$B9) -> 0 | E9: =D9*(1+$B9) -> 0 | F9: =E9*(1+$B9) -> 0 | G9: =F9*(1+$B9) -> 0 | H9: =G9*(1+$B9) -> 0 | I9: =H9*(1+$B9) -> 0 | J9: =I9*(1+$B9) -> 0 | K9: =J9*(1+$B9) -> 0 | ... N9: =M9*(1+$B9) -> 0 | O9: =SUM(C9:N9) -> 0
A10: =IF('2. Simulador de Meta'!A11="","",'2. Simulador de Meta'!A11) | B10: =$C$4 -> 0 | C10: ='2. Simulador de Meta'!F11 -> 0 | D10: =C10*(1+$B10) -> 0 | E10: =D10*(1+$B10) -> 0 | F10: =E10*(1+$B10) -> 0 | G10: =F10*(1+$B10) -> 0 | H10: =G10*(1+$B10) -> 0 | I10: =H10*(1+$B10) -> 0 | J10: =I10*(1+$B10) -> 0 | K10: =J10*(1+$B10) -> 0 | ... N10: =M10*(1+$B10) -> 0 | O10: =SUM(C10:N10) -> 0
A11: =IF('2. Simulador de Meta'!A12="","",'2. Simulador de Meta'!A12) | B11: =$C$4 -> 0 | C11: ='2. Simulador de Meta'!F12 -> 0 | D11: =C11*(1+$B11) -> 0 | E11: =D11*(1+$B11) -> 0 | F11: =E11*(1+$B11) -> 0 | G11: =F11*(1+$B11) -> 0 | H11: =G11*(1+$B11) -> 0 | I11: =H11*(1+$B11) -> 0 | J11: =I11*(1+$B11) -> 0 | K11: =J11*(1+$B11) -> 0 | ... N11: =M11*(1+$B11) -> 0 | O11: =SUM(C11:N11) -> 0
A12: =IF('2. Simulador de Meta'!A13="","",'2. Simulador de Meta'!A13) | B12: =$C$4 -> 0 | C12: ='2. Simulador de Meta'!F13 -> 0 | D12: =C12*(1+$B12) -> 0 | E12: =D12*(1+$B12) -> 0 | F12: =E12*(1+$B12) -> 0 | G12: =F12*(1+$B12) -> 0 | H12: =G12*(1+$B12) -> 0 | I12: =H12*(1+$B12) -> 0 | J12: =I12*(1+$B12) -> 0 | K12: =J12*(1+$B12) -> 0 | ... N12: =M12*(1+$B12) -> 0 | O12: =SUM(C12:N12) -> 0
A13: =IF('2. Simulador de Meta'!A14="","",'2. Simulador de Meta'!A14) | B13: =$C$4 -> 0 | C13: ='2. Simulador de Meta'!F14 -> 0 | D13: =C13*(1+$B13) -> 0 | E13: =D13*(1+$B13) -> 0 | F13: =E13*(1+$B13) -> 0 | G13: =F13*(1+$B13) -> 0 | H13: =G13*(1+$B13) -> 0 | I13: =H13*(1+$B13) -> 0 | J13: =I13*(1+$B13) -> 0 | K13: =J13*(1+$B13) -> 0 | ... N13: =M13*(1+$B13) -> 0 | O13: =SUM(C13:N13) -> 0
A14: =IF('2. Simulador de Meta'!A15="","",'2. Simulador de Meta'!A15) | B14: =$C$4 -> 0 | C14: ='2. Simulador de Meta'!F15 -> 0 | D14: =C14*(1+$B14) -> 0 | E14: =D14*(1+$B14) -> 0 | F14: =E14*(1+$B14) -> 0 | G14: =F14*(1+$B14) -> 0 | H14: =G14*(1+$B14) -> 0 | I14: =H14*(1+$B14) -> 0 | J14: =I14*(1+$B14) -> 0 | K14: =J14*(1+$B14) -> 0 | ... N14: =M14*(1+$B14) -> 0 | O14: =SUM(C14:N14) -> 0
A15: =IF('2. Simulador de Meta'!A16="","",'2. Simulador de Meta'!A16) | B15: =$C$4 -> 0 | C15: ='2. Simulador de Meta'!F16 -> 0 | D15: =C15*(1+$B15) -> 0 | E15: =D15*(1+$B15) -> 0 | F15: =E15*(1+$B15) -> 0 | G15: =F15*(1+$B15) -> 0 | H15: =G15*(1+$B15) -> 0 | I15: =H15*(1+$B15) -> 0 | J15: =I15*(1+$B15) -> 0 | K15: =J15*(1+$B15) -> 0 | ... N15: =M15*(1+$B15) -> 0 | O15: =SUM(C15:N15) -> 0
A16: =IF('2. Simulador de Meta'!A17="","",'2. Simulador de Meta'!A17) | B16: =$C$4 -> 0 | C16: ='2. Simulador de Meta'!F17 -> 0 | D16: =C16*(1+$B16) -> 0 | E16: =D16*(1+$B16) -> 0 | F16: =E16*(1+$B16) -> 0 | G16: =F16*(1+$B16) -> 0 | H16: =G16*(1+$B16) -> 0 | I16: =H16*(1+$B16) -> 0 | J16: =I16*(1+$B16) -> 0 | K16: =J16*(1+$B16) -> 0 | ... N16: =M16*(1+$B16) -> 0 | O16: =SUM(C16:N16) -> 0
A17: =IF('2. Simulador de Meta'!A18="","",'2. Simulador de Meta'!A18) | B17: =$C$4 -> 0 | C17: ='2. Simulador de Meta'!F18 -> 0 | D17: =C17*(1+$B17) -> 0 | E17: =D17*(1+$B17) -> 0 | F17: =E17*(1+$B17) -> 0 | G17: =F17*(1+$B17) -> 0 | H17: =G17*(1+$B17) -> 0 | I17: =H17*(1+$B17) -> 0 | J17: =I17*(1+$B17) -> 0 | K17: =J17*(1+$B17) -> 0 | ... N17: =M17*(1+$B17) -> 0 | O17: =SUM(C17:N17) -> 0
A18: =IF('2. Simulador de Meta'!A19="","",'2. Simulador de Meta'!A19) | B18: =$C$4 -> 0 | C18: ='2. Simulador de Meta'!F19 -> 0 | D18: =C18*(1+$B18) -> 0 | E18: =D18*(1+$B18) -> 0 | F18: =E18*(1+$B18) -> 0 | G18: =F18*(1+$B18) -> 0 | H18: =G18*(1+$B18) -> 0 | I18: =H18*(1+$B18) -> 0 | J18: =I18*(1+$B18) -> 0 | K18: =J18*(1+$B18) -> 0 | ... N18: =M18*(1+$B18) -> 0 | O18: =SUM(C18:N18) -> 0
... A21: =IF('2. Simulador de Meta'!A22="","",'2. Simulador de Meta'!A22) -> Canal novo 3 (escreva aqui) | B21: =$C$4 -> 0 | C21: ='2. Simulador de Meta'!F22 -> 0 | D21: =C21*(1+$B21) -> 0 | E21: =D21*(1+$B21) -> 0 | F21: =E21*(1+$B21) -> 0 | G21: =F21*(1+$B21) -> 0 | H21: =G21*(1+$B21) -> 0 | I21: =H21*(1+$B21) -> 0 | J21: =I21*(1+$B21) -> 0 | K21: =J21*(1+$B21) -> 0 | ... N21: =M21*(1+$B21) -> 0 | O21: =SUM(C21:N21) -> 0
A22: TOTAL | C22: =SUM(C7:C21) -> 80000 | D22: =SUM(D7:D21) -> 80000 | E22: =SUM(E7:E21) -> 80000 | F22: =SUM(F7:F21) -> 80000 | G22: =SUM(G7:G21) -> 80000 | H22: =SUM(H7:H21) -> 80000 | I22: =SUM(I7:I21) -> 80000 | J22: =SUM(J7:J21) -> 80000 | ... O22: =SUM(O7:O21) -> 960000
A24: COMO LER ESSA PROJEÇÃO
A25: • Renomeie «Mês 1, Mês 2...» para os meses do seu ciclo (Jan, Fev, Mar...). Mês 1 é o mês que você simulou na aba 2.
A26: • Crescimento não é fé: é consequência de mais entradas, melhor conversão ou ticket maior. Se você colocou 5% ao mês numa fonte, escreva na aba 5 QUAL atividade vai produzir esses 5%.
A27: • Fontes diferentes crescem em ritmos diferentes. Indicação cresce com processo; inbound cresce com investimento; carteira ativa cresce com cadência de contato. Ajuste a coluna B fonte a fonte.
A28: • Se a projeção do ano parece impossível, ela está te dizendo algo útil: ou a meta precisa mudar, ou o plano precisa de uma fonte nova — não de mais esforço na mesma.

Sheet 4. Acompanhamento
A1: 4. ACOMPANHAMENTO — META VS. REALIZADO
A2: O material do comitê de receita semanal/mensal: onde o plano está acontecendo e onde não está
A4: META POR FONTE (vem da projeção — aba 3)
A5: Fonte de receita | B5: Mês 1 | C5: Mês 2 | D5: Mês 3 | E5: Mês 4 | F5: Mês 5 | G5: Mês 6 | H5: Mês 7 | I5: Mês 8 | J5: Mês 9 | K5: Mês 10 | L5: Mês 11 | M5: Mês 12
A6: =IF('3. Projeção 12 meses'!A7="","",'3. Projeção 12 meses'!A7) -> Indicação (exemplo — apague e coloque as suas) | B6: ='3. Projeção 12 meses'!C7 -> 80000 | C6: ='3. Projeção 12 meses'!D7 -> 80000 | D6: ='3. Projeção 12 meses'!E7 -> 80000 | E6: ='3. Projeção 12 meses'!F7 -> 80000 | F6: ='3. Projeção 12 meses'!G7 -> 80000 | G6: ='3. Projeção 12 meses'!H7 -> 80000 | H6: ='3. Projeção 12 meses'!I7 -> 80000 | I6: ='3. Projeção 12 meses'!J7 -> 80000 | ... M6: ='3. Projeção 12 meses'!N7 -> 80000
A7: =IF('3. Projeção 12 meses'!A8="","",'3. Projeção 12 meses'!A8) | B7: ='3. Projeção 12 meses'!C8 -> 0 | C7: ='3. Projeção 12 meses'!D8 -> 0 | D7: ='3. Projeção 12 meses'!E8 -> 0 | E7: ='3. Projeção 12 meses'!F8 -> 0 | F7: ='3. Projeção 12 meses'!G8 -> 0 | G7: ='3. Projeção 12 meses'!H8 -> 0 | H7: ='3. Projeção 12 meses'!I8 -> 0 | I7: ='3. Projeção 12 meses'!J8 -> 0 | ... M7: ='3. Projeção 12 meses'!N8 -> 0
A8: =IF('3. Projeção 12 meses'!A9="","",'3. Projeção 12 meses'!A9) | B8: ='3. Projeção 12 meses'!C9 -> 0 | C8: ='3. Projeção 12 meses'!D9 -> 0 | D8: ='3. Projeção 12 meses'!E9 -> 0 | E8: ='3. Projeção 12 meses'!F9 -> 0 | F8: ='3. Projeção 12 meses'!G9 -> 0 | G8: ='3. Projeção 12 meses'!H9 -> 0 | H8: ='3. Projeção 12 meses'!I9 -> 0 | I8: ='3. Projeção 12 meses'!J9 -> 0 | ... M8: ='3. Projeção 12 meses'!N9 -> 0
A9: =IF('3. Projeção 12 meses'!A10="","",'3. Projeção 12 meses'!A10) | B9: ='3. Projeção 12 meses'!C10 -> 0 | C9: ='3. Projeção 12 meses'!D10 -> 0 | D9: ='3. Projeção 12 meses'!E10 -> 0 | E9: ='3. Projeção 12 meses'!F10 -> 0 | F9: ='3. Projeção 12 meses'!G10 -> 0 | G9: ='3. Projeção 12 meses'!H10 -> 0 | H9: ='3. Projeção 12 meses'!I10 -> 0 | I9: ='3. Projeção 12 meses'!J10 -> 0 | ... M9: ='3. Projeção 12 meses'!N10 -> 0
A10: =IF('3. Projeção 12 meses'!A11="","",'3. Projeção 12 meses'!A11) | B10: ='3. Projeção 12 meses'!C11 -> 0 | C10: ='3. Projeção 12 meses'!D11 -> 0 | D10: ='3. Projeção 12 meses'!E11 -> 0 | E10: ='3. Projeção 12 meses'!F11 -> 0 | F10: ='3. Projeção 12 meses'!G11 -> 0 | G10: ='3. Projeção 12 meses'!H11 -> 0 | H10: ='3. Projeção 12 meses'!I11 -> 0 | I10: ='3. Projeção 12 meses'!J11 -> 0 | ... M10: ='3. Projeção 12 meses'!N11 -> 0
A11: =IF('3. Projeção 12 meses'!A12="","",'3. Projeção 12 meses'!A12) | B11: ='3. Projeção 12 meses'!C12 -> 0 | C11: ='3. Projeção 12 meses'!D12 -> 0 | D11: ='3. Projeção 12 meses'!E12 -> 0 | E11: ='3. Projeção 12 meses'!F12 -> 0 | F11: ='3. Projeção 12 meses'!G12 -> 0 | G11: ='3. Projeção 12 meses'!H12 -> 0 | H11: ='3. Projeção 12 meses'!I12 -> 0 | I11: ='3. Projeção 12 meses'!J12 -> 0 | ... M11: ='3. Projeção 12 meses'!N12 -> 0
A12: =IF('3. Projeção 12 meses'!A13="","",'3. Projeção 12 meses'!A13) | B12: ='3. Projeção 12 meses'!C13 -> 0 | C12: ='3. Projeção 12 meses'!D13 -> 0 | D12: ='3. Projeção 12 meses'!E13 -> 0 | E12: ='3. Projeção 12 meses'!F13 -> 0 | F12: ='3. Projeção 12 meses'!G13 -> 0 | G12: ='3. Projeção 12 meses'!H13 -> 0 | H12: ='3. Projeção 12 meses'!I13 -> 0 | I12: ='3. Projeção 12 meses'!J13 -> 0 | ... M12: ='3. Projeção 12 meses'!N13 -> 0
A13: =IF('3. Projeção 12 meses'!A14="","",'3. Projeção 12 meses'!A14) | B13: ='3. Projeção 12 meses'!C14 -> 0 | C13: ='3. Projeção 12 meses'!D14 -> 0 | D13: ='3. Projeção 12 meses'!E14 -> 0 | E13: ='3. Projeção 12 meses'!F14 -> 0 | F13: ='3. Projeção 12 meses'!G14 -> 0 | G13: ='3. Projeção 12 meses'!H14 -> 0 | H13: ='3. Projeção 12 meses'!I14 -> 0 | I13: ='3. Projeção 12 meses'!J14 -> 0 | ... M13: ='3. Projeção 12 meses'!N14 -> 0
A14: =IF('3. Projeção 12 meses'!A15="","",'3. Projeção 12 meses'!A15) | B14: ='3. Projeção 12 meses'!C15 -> 0 | C14: ='3. Projeção 12 meses'!D15 -> 0 | D14: ='3. Projeção 12 meses'!E15 -> 0 | E14: ='3. Projeção 12 meses'!F15 -> 0 | F14: ='3. Projeção 12 meses'!G15 -> 0 | G14: ='3. Projeção 12 meses'!H15 -> 0 | H14: ='3. Projeção 12 meses'!I15 -> 0 | I14: ='3. Projeção 12 meses'!J15 -> 0 | ... M14: ='3. Projeção 12 meses'!N15 -> 0
A15: =IF('3. Projeção 12 meses'!A16="","",'3. Projeção 12 meses'!A16) | B15: ='3. Projeção 12 meses'!C16 -> 0 | C15: ='3. Projeção 12 meses'!D16 -> 0 | D15: ='3. Projeção 12 meses'!E16 -> 0 | E15: ='3. Projeção 12 meses'!F16 -> 0 | F15: ='3. Projeção 12 meses'!G16 -> 0 | G15: ='3. Projeção 12 meses'!H16 -> 0 | H15: ='3. Projeção 12 meses'!I16 -> 0 | I15: ='3. Projeção 12 meses'!J16 -> 0 | ... M15: ='3. Projeção 12 meses'!N16 -> 0
A16: =IF('3. Projeção 12 meses'!A17="","",'3. Projeção 12 meses'!A17) | B16: ='3. Projeção 12 meses'!C17 -> 0 | C16: ='3. Projeção 12 meses'!D17 -> 0 | D16: ='3. Projeção 12 meses'!E17 -> 0 | E16: ='3. Projeção 12 meses'!F17 -> 0 | F16: ='3. Projeção 12 meses'!G17 -> 0 | G16: ='3. Projeção 12 meses'!H17 -> 0 | H16: ='3. Projeção 12 meses'!I17 -> 0 | I16: ='3. Projeção 12 meses'!J17 -> 0 | ... M16: ='3. Projeção 12 meses'!N17 -> 0
A17: =IF('3. Projeção 12 meses'!A18="","",'3. Projeção 12 meses'!A18) | B17: ='3. Projeção 12 meses'!C18 -> 0 | C17: ='3. Projeção 12 meses'!D18 -> 0 | D17: ='3. Projeção 12 meses'!E18 -> 0 | E17: ='3. Projeção 12 meses'!F18 -> 0 | F17: ='3. Projeção 12 meses'!G18 -> 0 | G17: ='3. Projeção 12 meses'!H18 -> 0 | H17: ='3. Projeção 12 meses'!I18 -> 0 | I17: ='3. Projeção 12 meses'!J18 -> 0 | ... M17: ='3. Projeção 12 meses'!N18 -> 0
... A20: =IF('3. Projeção 12 meses'!A21="","",'3. Projeção 12 meses'!A21) -> Canal novo 3 (escreva aqui) | B20: ='3. Projeção 12 meses'!C21 -> 0 | C20: ='3. Projeção 12 meses'!D21 -> 0 | D20: ='3. Projeção 12 meses'!E21 -> 0 | E20: ='3. Projeção 12 meses'!F21 -> 0 | F20: ='3. Projeção 12 meses'!G21 -> 0 | G20: ='3. Projeção 12 meses'!H21 -> 0 | H20: ='3. Projeção 12 meses'!I21 -> 0 | I20: ='3. Projeção 12 meses'!J21 -> 0 | ... M20: ='3. Projeção 12 meses'!N21 -> 0
A21: TOTAL | B21: =SUM(B6:B20) -> 80000 | C21: =SUM(C6:C20) -> 80000 | D21: =SUM(D6:D20) -> 80000 | E21: =SUM(E6:E20) -> 80000 | F21: =SUM(F6:F20) -> 80000 | G21: =SUM(G6:G20) -> 80000 | H21: =SUM(H6:H20) -> 80000 | I21: =SUM(I6:I20) -> 80000 | ... M21: =SUM(M6:M20) -> 80000
A23: REALIZADO POR FONTE (você preenche mês a mês)
A24: Fonte de receita | B24: Mês 1 | C24: Mês 2 | D24: Mês 3 | E24: Mês 4 | F24: Mês 5 | G24: Mês 6 | H24: Mês 7 | I24: Mês 8 | J24: Mês 9 | K24: Mês 10 | L24: Mês 11 | M24: Mês 12
A25: =IF('3. Projeção 12 meses'!A7="","",'3. Projeção 12 meses'!A7) -> Indicação (exemplo — apague e coloque as suas)
A26: =IF('3. Projeção 12 meses'!A8="","",'3. Projeção 12 meses'!A8)
A27: =IF('3. Projeção 12 meses'!A9="","",'3. Projeção 12 meses'!A9)
A28: =IF('3. Projeção 12 meses'!A10="","",'3. Projeção 12 meses'!A10)
A29: =IF('3. Projeção 12 meses'!A11="","",'3. Projeção 12 meses'!A11)
A30: =IF('3. Projeção 12 meses'!A12="","",'3. Projeção 12 meses'!A12)
A31: =IF('3. Projeção 12 meses'!A13="","",'3. Projeção 12 meses'!A13)
A32: =IF('3. Projeção 12 meses'!A14="","",'3. Projeção 12 meses'!A14)
A33: =IF('3. Projeção 12 meses'!A15="","",'3. Projeção 12 meses'!A15)
A34: =IF('3. Projeção 12 meses'!A16="","",'3. Projeção 12 meses'!A16)
A35: =IF('3. Projeção 12 meses'!A17="","",'3. Projeção 12 meses'!A17)
A36: =IF('3. Projeção 12 meses'!A18="","",'3. Projeção 12 meses'!A18)
... A39: =IF('3. Projeção 12 meses'!A21="","",'3. Projeção 12 meses'!A21) -> Canal novo 3 (escreva aqui)
A40: TOTAL | B40: =SUM(B25:B39) -> 0 | C40: =SUM(C25:C39) -> 0 | D40: =SUM(D25:D39) -> 0 | E40: =SUM(E25:E39) -> 0 | F40: =SUM(F25:F39) -> 0 | G40: =SUM(G25:G39) -> 0 | H40: =SUM(H25:H39) -> 0 | I40: =SUM(I25:I39) -> 0 | ... M40: =SUM(M25:M39) -> 0
A42: % DA META ATINGIDA (calculado)
A43: Fonte de receita | B43: Mês 1 | C43: Mês 2 | D43: Mês 3 | E43: Mês 4 | F43: Mês 5 | G43: Mês 6 | H43: Mês 7 | I43: Mês 8 | J43: Mês 9 | K43: Mês 10 | L43: Mês 11 | M43: Mês 12
A44: =IF('3. Projeção 12 meses'!A7="","",'3. Projeção 12 meses'!A7) -> Indicação (exemplo — apague e coloque as suas) | B44: =IF(B25="","",IFERROR(B25/B6,"")) | C44: =IF(C25="","",IFERROR(C25/C6,"")) | D44: =IF(D25="","",IFERROR(D25/D6,"")) | E44: =IF(E25="","",IFERROR(E25/E6,"")) | F44: =IF(F25="","",IFERROR(F25/F6,"")) | G44: =IF(G25="","",IFERROR(G25/G6,"")) | H44: =IF(H25="","",IFERROR(H25/H6,"")) | I44: =IF(I25="","",IFERROR(I25/I6,"")) | ... M44: =IF(M25="","",IFERROR(M25/M6,""))
A45: =IF('3. Projeção 12 meses'!A8="","",'3. Projeção 12 meses'!A8) | B45: =IF(B26="","",IFERROR(B26/B7,"")) | C45: =IF(C26="","",IFERROR(C26/C7,"")) | D45: =IF(D26="","",IFERROR(D26/D7,"")) | E45: =IF(E26="","",IFERROR(E26/E7,"")) | F45: =IF(F26="","",IFERROR(F26/F7,"")) | G45: =IF(G26="","",IFERROR(G26/G7,"")) | H45: =IF(H26="","",IFERROR(H26/H7,"")) | I45: =IF(I26="","",IFERROR(I26/I7,"")) | ... M45: =IF(M26="","",IFERROR(M26/M7,""))
A46: =IF('3. Projeção 12 meses'!A9="","",'3. Projeção 12 meses'!A9) | B46: =IF(B27="","",IFERROR(B27/B8,"")) | C46: =IF(C27="","",IFERROR(C27/C8,"")) | D46: =IF(D27="","",IFERROR(D27/D8,"")) | E46: =IF(E27="","",IFERROR(E27/E8,"")) | F46: =IF(F27="","",IFERROR(F27/F8,"")) | G46: =IF(G27="","",IFERROR(G27/G8,"")) | H46: =IF(H27="","",IFERROR(H27/H8,"")) | I46: =IF(I27="","",IFERROR(I27/I8,"")) | ... M46: =IF(M27="","",IFERROR(M27/M8,""))
A47: =IF('3. Projeção 12 meses'!A10="","",'3. Projeção 12 meses'!A10) | B47: =IF(B28="","",IFERROR(B28/B9,"")) | C47: =IF(C28="","",IFERROR(C28/C9,"")) | D47: =IF(D28="","",IFERROR(D28/D9,"")) | E47: =IF(E28="","",IFERROR(E28/E9,"")) | F47: =IF(F28="","",IFERROR(F28/F9,"")) | G47: =IF(G28="","",IFERROR(G28/G9,"")) | H47: =IF(H28="","",IFERROR(H28/H9,"")) | I47: =IF(I28="","",IFERROR(I28/I9,"")) | ... M47: =IF(M28="","",IFERROR(M28/M9,""))
...

Sheet 5. Processos e Cadência
A1: 5. PROCESSOS E CADÊNCIA
A2: O plano só vira receita quando vira atividade com padrão, responsável e verificação
A4: Atividade é o que está no seu controle fazer. Fazer uma pessoa entrar na loja não está no seu controle; atendê-la depois que entrou, sim. Uma atividade só vira processo de verdade quando tem 3 coisas: um PADRÃO que qualquer pessoa consegue seguir desde o primeiro dia, um RESPONSÁVEL com nome e sobrenome, e uma FORMA DE VERIFICAR se foi feito.
A5: «Vou fazer 5 ligações por dia» é controle. «Vou vender mais» é só visibilidade.
A7: O QUE PRECISA SER FEITO, QUANTAS VEZES, COMO E POR QUEM — comece pelas suas 2 ou 3 principais fontes
A8: Fonte de receita | B8: Atividade-chave | C8: Padrão (como exatamente é feito) | D8: Responsável (nome e sobrenome) | E8: Meta de atividade (quantas vezes) | F8: Frequência | G8: Como verificar se aconteceu
A9: Indicação (exemplo) | B9: Pedir indicação ao fim de cada entrega | C9: No call de encerramento, pedir 2 nomes e o contexto de cada um antes de encerrar a chamada | D9: Marina Alves | E9: 100% dos projetos encerrados | F9: A cada entrega | G9: Campo «indicações pedidas» preenchido no CRM
A10: Inbound (exemplo) | B10: Primeiro atendimento do lead | C10: Responder todo lead em até 5 minutos, por telefone antes de WhatsApp, com pergunta de contexto antes de preço | D10: Rafael Lima | E10: 100% dos leads em até 5 min | F10: Diária | G10: Relatório de tempo de primeira resposta, revisado toda segunda
A22: OS 3 RITUAIS QUE SUSTENTAM A OPERAÇÃO — marque na agenda, mesmo que seja só você
A23: Ritual | B23: Frequência | C23: O que olhar | D23: Formato | E23: Quem conduz | F23: Dia e hora na agenda
A24: Matinal | B24: Diária · 15 min | C24: Prioridades do dia, travamentos, próximos passos | D24: Em pé, sem pauta longa
A25: Comitê de receita | B25: Semanal · 30 min | C25: Meta vs. realizado por fonte (aba 4), indicadores de direção, ações | D25: Tabela na tela + UMA decisão concreta
A26: Planejamento | B26: Mensal · 1 a 2h | C26: Ajustes no plano, capacidade do time, novas iniciativas | D26: Revisão do sistema completo (abas 1 a 3)
A28: SE VOCÊ FIZER SÓ ISSO, JÁ PAGOU O MÊS
A29: Escreva, para as suas 3 principais fontes de receita, o que precisa ser feito, quantas vezes, como e por quem. Depois marque o comitê de receita semanal na agenda — mesmo que seja só você — e analise que atividades você pode fazer mais e melhor para vender mais.
A31: AS 7 PERGUNTAS PARA INVESTIGAR A SUA VENDA
A32: 1. Quais são as fontes de receita do meu negócio hoje? Eu tenho nome para cada uma delas?
A33: 2. Qual é a receita por entrada de cada fonte? Eu sei qual vale mais o meu tempo?
A34: 3. Para as atividades mais críticas de vender: existe padrão, responsável e forma de verificar?
A35: 4. Eu tenho rituais de vendas na agenda — matinal, comitê de receita semanal e planejamento mensal?
A36: 5. Qual foi a última vez que eu mesmo atendi ou ajudei a fechar um cliente?
A37: 6. Quantas vezes eu ofereci o meu produto ou serviço hoje?
A38: 7. Como eu ofereço meu produto ou serviço para 10, 20 ou 30 pessoas a mais essa semana?

Sheet Exemplo Serviço B2B
A1: EXEMPLO 1 · SERVIÇO B2B — ATIVA CONSULTORIA
A2: Consultoria de gestão financeira para PMEs · projetos de R$ 12 mil a R$ 25 mil · time de 9 pessoas
A4: O NEGÓCIO
A5: A Ativa vende projetos de estruturação financeira para empresas de R$ 5 a R$ 50 milhões de faturamento. Fatura cerca de R$ 357 mil por mês e cresce, mas o sócio não sabe explicar de onde vem o crescimento — nos meses bons ele diz «foi um mês bom».
A6: O time comercial tem 1 sócio vendendo, 1 executivo de contas e 1 SDR fazendo prospecção ativa. A sensação do sócio, antes do plano: «prospecção ativa é o motor da empresa, é onde a gente mais trabalha». Os números abaixo mostram outra coisa.
A7: Período do plano: um mês fechado. Entrada = qualquer contato inicial (formulário do site, resposta de e-mail frio, indicação recebida, contato em evento). Proposta = documento comercial enviado com escopo e preço.
A9: O PLANO DE RECEITA — NÍVEIS 1, 2 E 3
A10: Fonte de receita | B10: Entradas (leads) | C10: Propostas | D10: Vendas | E10: Receita (R$) | F10: Ticket médio | G10: Conv. entrada→propostas | H10: Conv. →venda | I10: Conv. entrada→venda | J10: Receita por entrada | K10: % da receita
A11: Inbound (site, Google, conteúdo) | B11: 110 | C11: 22 | D11: 5 | E11: 90000 | F11: =IFERROR(E11/D11,"") -> 18000 | G11: =IFERROR(C11/B11,"") -> 0.2 | H11: =IFERROR(D11/C11,"") -> 0.22727273 | I11: =IFERROR(D11/B11,"") -> 0.045454545 | J11: =IFERROR(E11/B11,"") -> 818.18182 | K11: =IFERROR(E11/$E$17,"") -> 0.25210084
A12: Indicação de clientes | B12: 8 | C12: 6 | D12: 4 | E12: 100000 | F12: =IFERROR(E12/D12,"") -> 25000 | G12: =IFERROR(C12/B12,"") -> 0.75 | H12: =IFERROR(D12/C12,"") -> 0.66666667 | I12: =IFERROR(D12/B12,"") -> 0.5 | J12: =IFERROR(E12/B12,"") -> 12500 | K12: =IFERROR(E12/$E$17,"") -> 0.28011204
A13: Prospecção ativa (SDR) | B13: 140 | C13: 14 | D13: 2 | E13: 44000 | F13: =IFERROR(E13/D13,"") -> 22000 | G13: =IFERROR(C13/B13,"") -> 0.1 | H13: =IFERROR(D13/C13,"") -> 0.14285714 | I13: =IFERROR(D13/B13,"") -> 0.014285714 | J13: =IFERROR(E13/B13,"") -> 314.28571 | K13: =IFERROR(E13/$E$17,"") -> 0.1232493
A14: Carteira ativa (expansão de escopo) | B14: 20 | C14: 10 | D14: 5 | E14: 60000 | F14: =IFERROR(E14/D14,"") -> 12000 | G14: =IFERROR(C14/B14,"") -> 0.5 | H14: =IFERROR(D14/C14,"") -> 0.5 | I14: =IFERROR(D14/B14,"") -> 0.25 | J14: =IFERROR(E14/B14,"") -> 3000 | K14: =IFERROR(E14/$E$17,"") -> 0.16806723
A15: Parcerias (contadores e bancos) | B15: 12 | C15: 7 | D15: 2 | E15: 44000 | F15: =IFERROR(E15/D15,"") -> 22000 | G15: =IFERROR(C15/B15,"") -> 0.58333333 | H15: =IFERROR(D15/C15,"") -> 0.28571429 | I15: =IFERROR(D15/B15,"") -> 0.16666667 | J15: =IFERROR(E15/B15,"") -> 3666.6667 | K15: =IFERROR(E15/$E$17,"") -> 0.1232493
A16: Eventos e palestras | B16: 30 | C16: 6 | D16: 1 | E16: 19000 | F16: =IFERROR(E16/D16,"") -> 19000 | G16: =IFERROR(C16/B16,"") -> 0.2 | H16: =IFERROR(D16/C16,"") -> 0.16666667 | I16: =IFERROR(D16/B16,"") -> 0.033333333 | J16: =IFERROR(E16/B16,"") -> 633.33333 | K16: =IFERROR(E16/$E$17,"") -> 0.053221289
A17: TOTAL | B17: =SUM(B11:B16) -> 320 | C17: =SUM(C11:C16) -> 65 | D17: =SUM(D11:D16) -> 19 | E17: =SUM(E11:E16) -> 357000 | F17: =IFERROR(E17/D17,"") -> 18789.474 | G17: =IFERROR(C17/B17,"") -> 0.203125 | H17: =IFERROR(D17/C17,"") -> 0.29230769 | I17: =IFERROR(D17/B17,"") -> 0.059375 | J17: =IFERROR(E17/B17,"") -> 1115.625 | K17: =SUM(K11:K16) -> 1
A19: COMO LER ESSE PLANO — o que esses números estão dizendo
A20: 1. Nível 1 · A maior fonte não é a que parece | B20: Indicação gera R$ 100 mil por mês — a maior fatia da receita (28%) — com apenas 8 entradas. Prospecção ativa, onde o time gasta a maior parte do dia, gera R$ 44 mil (12%). O sócio achava que o motor era a prospecção porque é onde há mais movimento, não mais dinheiro. Movimento não é receita.
A21: 2. Nível 2 · O gargalo do inbound está no meio do funil | B21: O inbound recebe 110 entradas e transforma só 22 em proposta (20%). São 88 pessoas por mês que levantaram a mão e nunca receberam um preço. Não é problema de geração de lead — é problema de atendimento. Comprar mais lead antes de arrumar isso é jogar dinheiro em um funil furado.
A22: 3. Nível 2 · A prospecção não está errada, está mal calibrada | B22: 140 entradas viram 14 propostas e 2 vendas: 1,4% de conversão entrada→venda, a pior do plano. O problema não é o SDR trabalhar pouco — é a lista e a abordagem. Antes de contratar o segundo SDR, o dono precisa arrumar quem esse SDR aborda e com qual frase.
A23: 4. Nível 3 · Uma indicação vale 40 prospecções | B23: Cada entrada de indicação gera R$ 12.500 de receita. Cada entrada de prospecção ativa gera R$ 314. É 40 vezes mais. Se o sócio tem 1 hora livre para vender, ela rende 40x mais pedindo indicação do que fazendo ligação fria. Esse é o número que muda a agenda do dono.
A24: 5. Nível 3 · Inbound é volume, indicação é valor — e cada um pede uma ação diferente | B24: Inbound tem R$ 818 por entrada e 110 entradas. Melhorar R$ 100 na receita por entrada do inbound vale R$ 11 mil por mês, sem nenhuma entrada nova. Indicação tem poucas entradas e valor altíssimo: aqui o jogo é gerar mais entradas, não otimizar. Canal de volume se otimiza; canal de valor se multiplica.
A25: 6. O ponto cego | B25: Indicação é a maior fonte de receita da empresa e é a única sem nenhum processo: acontece quando o cliente lembra. Uma fonte de R$ 100 mil por mês rodando por sorte é o maior risco do negócio — e, ao mesmo tempo, a maior oportunidade.
A27: A DECISÃO QUE ESSE PLANO GERA
A28: → Transformar indicação em processo, não em sorte: pedir 2 nomes no call de encerramento de todo projeto, com responsável, meta (100% das entregas) e verificação no CRM. Meta: sair de 8 para 16 entradas por mês.
A29: → Arrumar o meio do funil do inbound antes de comprar mais tráfego: responder todo lead em até 5 minutos e subir a conversão entrada→proposta de 20% para 35%.
A30: → Congelar a expansão da prospecção ativa por 60 dias. Não cortar — recalibrar lista e abordagem, e só voltar a escalar quando a conversão entrada→venda passar de 1,4% para 3%.
A31: → Manter tudo que já funciona. Crescer é empilhar fontes que funcionam, não trocar a aposta: a carteira ativa continua com a mesma cadência de contato.
A33: SIMULAÇÃO — o que acontece se o dono puxar as alavancas certas
A34: Movimento | B34: Alavanca | C34: Hoje | D34: Depois do movimento | E34: Impacto na receita (R$/mês) | F34: Custo do movimento e observação
A35: Dobrar as indicações | B35: Mais entradas | C35: 8 entradas/mês | D35: 16 entradas/mês | E35: 100000 | F35: Custo: R$ 0. Só um processo no encerramento de projeto. É a receita mais barata do plano inteiro.
A36: Arrumar o funil do inbound | B36: Melhor conversão | C36: 20% entrada→proposta | D36: 35% entrada→proposta | E36: 67500 | F36: Custo: uma regra de resposta em 5 minutos. As 110 entradas já foram pagas — só estavam sendo desperdiçadas.
A37: Recalibrar a prospecção ativa | B37: Melhor conversão | C37: 1,4% entrada→venda | D37: 3,0% entrada→venda | E37: 48400 | F37: Custo: tempo de revisão de lista e script. Sem contratar o segundo SDR.
A38: GANHO TOTAL DO MÊS | E38: =SUM(E35:E37) -> 215900 | F38: De R$ 357 mil para R$ 573 mil por mês sem contratar ninguém e sem aumentar o investimento em mídia.
A40: A LIÇÃO DESSE EXEMPLO
A41: O plano de receita não inventou nenhum canal novo. Ele só deu nome ao que já existia — e mostrou que a empresa estava colocando o maior esforço (prospecção) na entrada que vale 40 vezes menos, enquanto a fonte mais rentável (indicação) rodava sem processo, sem dono e sem meta. É isso que fazer gestão de receita significa: saber de onde o dinheiro vem, olhar cada fonte separadamente e montar um plano específico para cada uma.

Sheet Exemplo Loja Física
A1: EXEMPLO 2 · VAREJO — LOJA ORIGEM
A2: Loja de moda masculina de rua · 1 unidade · 4 vendedores · faturamento de R$ 142 mil/mês
A4: O NEGÓCIO
A5: A Origem é uma loja de rua com boa localização, 4 vendedores e 9 anos de estrada. O dono acompanha faturamento e ticket médio, mas nunca separou a receita por origem — para ele, «venda é venda». Quando o mês cai, a explicação é sempre a mesma: «o movimento da rua caiu».
A6: Ao separar as fontes, ele descobriu que só metade da receita depende do movimento da rua — e que a metade que ele controla é justamente a que ninguém cuida.
A7: Período do plano: um mês fechado. Entrada = pessoa que entra na loja, conversa iniciada no WhatsApp, clique no anúncio, visita ao e-commerce ou contato de empresa. Atendimento = cliente que experimentou peça, pediu orçamento ou colocou item no carrinho. No varejo, «proposta» vira «atendimento» — o nome muda, a lógica é a mesma.
A9: O PLANO DE RECEITA — NÍVEIS 1, 2 E 3
A10: Fonte de receita | B10: Entradas (fluxo) | C10: Atendimentos | D10: Vendas | E10: Receita (R$) | F10: Ticket médio | G10: Conv. entrada→atendimentos | H10: Conv. →venda | I10: Conv. entrada→venda | J10: Receita por entrada | K10: % da receita
A11: Fluxo de rua (quem passa e entra) | B11: 1400 | C11: 560 | D11: 224 | E11: 71680 | F11: =IFERROR(E11/D11,"") -> 320 | G11: =IFERROR(C11/B11,"") -> 0.4 | H11: =IFERROR(D11/C11,"") -> 0.4 | I11: =IFERROR(D11/B11,"") -> 0.16 | J11: =IFERROR(E11/B11,"") -> 51.2 | K11: =IFERROR(E11/$E$17,"") -> 0.50454002
A12: Base de clientes no WhatsApp | B12: 260 | C12: 130 | D12: 78 | E12: 35100 | F12: =IFERROR(E12/D12,"") -> 450 | G12: =IFERROR(C12/B12,"") -> 0.5 | H12: =IFERROR(D12/C12,"") -> 0.6 | I12: =IFERROR(D12/B12,"") -> 0.3 | J12: =IFERROR(E12/B12,"") -> 135 | K12: =IFERROR(E12/$E$17,"") -> 0.24706131
A13: Instagram e anúncio local | B13: 180 | C13: 72 | D13: 25 | E13: 8750 | F13: =IFERROR(E13/D13,"") -> 350 | G13: =IFERROR(C13/B13,"") -> 0.4 | H13: =IFERROR(D13/C13,"") -> 0.34722222 | I13: =IFERROR(D13/B13,"") -> 0.13888889 | J13: =IFERROR(E13/B13,"") -> 48.611111 | K13: =IFERROR(E13/$E$17,"") -> 0.061589357
A14: Indicação de cliente | B14: 40 | C14: 28 | D14: 18 | E14: 7560 | F14: =IFERROR(E14/D14,"") -> 420 | G14: =IFERROR(C14/B14,"") -> 0.7 | H14: =IFERROR(D14/C14,"") -> 0.64285714 | I14: =IFERROR(D14/B14,"") -> 0.45 | J14: =IFERROR(E14/B14,"") -> 189 | K14: =IFERROR(E14/$E$17,"") -> 0.053213205
A15: Empresas e uniformes (B2B) | B15: 12 | C15: 6 | D15: 3 | E15: 12600 | F15: =IFERROR(E15/D15,"") -> 4200 | G15: =IFERROR(C15/B15,"") -> 0.5 | H15: =IFERROR(D15/C15,"") -> 0.5 | I15: =IFERROR(D15/B15,"") -> 0.25 | J15: =IFERROR(E15/B15,"") -> 1050 | K15: =IFERROR(E15/$E$17,"") -> 0.088688675
A16: E-commerce e marketplace | B16: 900 | C16: 90 | D16: 22 | E16: 6380 | F16: =IFERROR(E16/D16,"") -> 290 | G16: =IFERROR(C16/B16,"") -> 0.1 | H16: =IFERROR(D16/C16,"") -> 0.24444444 | I16: =IFERROR(D16/B16,"") -> 0.024444444 | J16: =IFERROR(E16/B16,"") -> 7.0888889 | K16: =IFERROR(E16/$E$17,"") -> 0.04490744
A17: TOTAL | B17: =SUM(B11:B16) -> 2792 | C17: =SUM(C11:C16) -> 886 | D17: =SUM(D11:D16) -> 370 | E17: =SUM(E11:E16) -> 142070 | F17: =IFERROR(E17/D17,"") -> 383.97297 | G17: =IFERROR(C17/B17,"") -> 0.31733524 | H17: =IFERROR(D17/C17,"") -> 0.41760722 | I17: =IFERROR(D17/B17,"") -> 0.13252149 | J17: =IFERROR(E17/B17,"") -> 50.88467 | K17: =SUM(K11:K16) -> 1
A19: COMO LER ESSE PLANO — o que esses números estão dizendo
A20: 1. Nível 1 · «Movimento caiu» explica metade do negócio, não o negócio inteiro | B20: O fluxo de rua responde por R$ 71,7 mil (50% da receita). A outra metade — WhatsApp da base, indicação, B2B, e-commerce — não depende de quem passa na calçada. Enquanto tudo era «venda é venda», o dono culpava a rua por um resultado que ele controlava em 50%.
A21: 2. Nível 2 · A conversão da loja é o ativo mais valioso e o menos gerenciado | B21: De 1.400 pessoas que entram, 560 são atendidas de verdade (40%) e 224 compram (16% do fluxo total). Ou seja: 840 pessoas por mês entram na loja e saem sem serem atendidas. Cada ponto percentual de conversão do fluxo vale cerca de R$ 4,5 mil por mês — sem gastar R$ 1 a mais de anúncio.
A22: 3. Nível 3 · Uma entrada B2B vale 20 fluxos de rua | B22: Cada contato de empresa gera R$ 1.050 de receita. Cada pessoa que entra na loja gera R$ 51. É 20 vezes mais. E o canal B2B teve 12 entradas no mês — todas passivas, ninguém foi atrás de nenhuma. É o canal mais rentável da loja rodando no automático.
A23: 4. Nível 3 · A base no WhatsApp é a alavanca mais barata que existe | B23: R$ 135 por entrada, ticket de R$ 450 (40% acima do fluxo de rua) e conversão de 30% — o dobro da loja. Faz sentido: é gente que já comprou e já confia. E essa lista já está no celular dos vendedores, sem custo de aquisição nenhum.
A24: 5. Nível 3 · O e-commerce está consumindo esforço e devolvendo centavos | B24: 900 visitas geram R$ 6,4 mil e R$ 7,09 por entrada — o pior do plano, com 2,4% de conversão. Isso não significa fechar. Significa parar de tratá-lo como aposta de crescimento enquanto a conversão não sair do lugar, e não colocar mais verba de mídia ali antes de arrumar o funil.
A25: 6. O ponto cego | B25: O dono estava prestes a contratar uma agência para «trazer mais gente para a loja». O plano mostrou que trazer mais gente é a alavanca mais cara — e que ele tinha 840 pessoas por mês entrando sem atendimento, uma lista de clientes parada e um canal B2B 20 vezes mais rentável sem dono.
A27: A DECISÃO QUE ESSE PLANO GERA
A28: → Definir processo de atendimento com padrão verificável: abordar em até 2 minutos, a 3 metros da porta, com pergunta de contexto («é a primeira vez aqui?») e oferta do produto-âncora em todo atendimento. Meta: subir a conversão do fluxo de 16% para 18%.
A29: → Dar dono ao canal B2B: um vendedor responsável por 20 contatos ativos por mês com empresas do bairro (escritórios, clínicas, concessionárias) — o canal mais rentável não pode continuar passivo.
A30: → Criar cadência de WhatsApp ativo: cada vendedor faz 15 conversas por dia com a base, com motivo real (peça nova do tamanho dele, aniversário, item que combina com a última compra). Meta: de 260 para 400 entradas por mês.
A31: → Segurar a verba nova de anúncio até a conversão da loja subir. Não faz sentido pagar para trazer gente que ninguém vai atender.
A33: SIMULAÇÃO — o que acontece se o dono puxar as alavancas certas
A34: Movimento | B34: Alavanca | C34: Hoje | D34: Depois do movimento | E34: Impacto na receita (R$/mês) | F34: Custo do movimento e observação
A35: Processo de atendimento na loja | B35: Melhor conversão | C35: 16% do fluxo compra | D35: 18% do fluxo compra | E35: 8960 | F35: Custo: treino de 1 hora e cobrança diária na matinal. As 1.400 entradas já estavam lá.
A36: Dar dono ao canal B2B | B36: Mais entradas | C36: 12 contatos/mês | D36: 24 contatos/mês | E36: 12600 | F36: Custo: R$ 0 de mídia. Um vendedor com meta de 20 contatos ativos por mês.
A37: Cadência de WhatsApp com a base | B37: Mais entradas | C37: 260 conversas/mês | D37: 400 conversas/mês | E37: 18900 | F37: Custo: R$ 0. A lista já existe. É a receita que estava dormindo no celular do time.
A38: Peça adicional no fechamento | B38: Ticket maior | C38: Ticket de R$ 320 | D38: Ticket de R$ 350 | E38: 6720 | F38: Custo: uma pergunta padrão no caixa. Vale para as 224 vendas do fluxo de rua.
A39: GANHO TOTAL DO MÊS | E39: =SUM(E35:E38) -> 47180 | F39: De R$ 142 mil para R$ 189 mil por mês — 33% a mais — sem um real a mais de anúncio e sem contratar ninguém.
A41: A LIÇÃO DESSE EXEMPLO
A42: No varejo, a tentação é sempre resolver venda com movimento: mais anúncio, mais gente na porta, mais promoção. O plano de receita mostra que as alavancas mais baratas quase sempre estão dentro de casa — na conversão de quem já entrou, na base que já comprou e no canal rentável que ninguém está olhando. Não existe mês ruim quando você sabe de onde a venda vem: existe alavanca que ninguém puxou.

Sheet Glossário
A1: GLOSSÁRIO E MÉTODO
A2: Os termos do plano de receita, em português de dono
A4: OS TERMOS
A5: Termo | B5: O que é | C5: Exemplo no seu negócio
A6: Fonte de receita | B6: A origem da venda. Cada fonte é, na prática, um dinheiro diferente: exige esforço diferente, converte diferente e vale diferente. | C6: Carteira ativa, indicação, prospecção ativa, inbound, eventos, parcerias, canal indireto, fluxo de loja, WhatsApp, marketplace.
A7: Entrada | B7: Todo contato inicial, seja qual for o formato. É o termo genérico que serve para qualquer negócio. | C7: Pessoa que entra na loja · lead que preenche formulário · orçamento pedido · visita agendada · DM respondida · ligação atendida.
A8: Proposta | B8: O meio do caminho entre a entrada e a venda. Se o seu negócio não tem essa etapa, adapte o nome — o que importa é medir o meio do funil. | C8: Proposta enviada · orçamento passado · cliente que experimentou a peça · degustação · aula experimental · carrinho montado.
A9: Venda | B9: O negócio fechado, atribuído à fonte que o originou. | C9: Contrato assinado · cupom emitido · pedido faturado.
A10: Conversão | B10: Quanto de uma etapa passa para a próxima. É o indicador de direção que mostra onde a venda trava. | C10: 100 entradas → 20 propostas = 20% de conversão entrada→proposta.
A11: Ticket médio | B11: Receita dividida por vendas. Quanto vale, em média, cada negócio fechado naquela fonte. | C11: R$ 90.000 de receita ÷ 5 vendas = R$ 18.000 de ticket médio.
A12: Receita por entrada | B12: Receita da fonte dividida pelas entradas da fonte. É o indicador do nível 3 — o que quase ninguém calcula e o que muda a decisão. | C12: R$ 100.000 ÷ 8 indicações = R$ 12.500 por entrada. Contra R$ 314 da prospecção ativa.
A13: Indicador de direção | B13: O número que você monitora antes do resultado aparecer: conversão, receita por entrada, cobertura, ciclo. | C13: Se as atividades acontecem e os indicadores de direção não se movem, o processo precisa ser revisto.
A14: Atividade | B14: Tudo o que está no seu controle fazer. Fazer alguém entrar na loja não está; atendê-la depois que entrou, sim. | C14: 10 ligações por dia · responder em 5 minutos · pedir 2 indicações por entrega.
A15: Processo | B15: Atividade com padrão, responsável e forma de verificar. Sem os 3, é intenção — e intenção não se ensina, não se mede e não se cobra. | C15: «Atender bem» é intenção. «Receber a 3 metros da porta em até 2 minutos e perguntar o que trouxe a pessoa» é processo.
A17: OS 3 ESTÁGIOS DE VENDAS — em qual você está?
A18: Estágio | B18: A pergunta que você faz | C18: O que define
A19: 01 · Reativo | B19: Quanto você está vendendo? | C19: Sem plano, sem processos, sem cadência. O resultado depende do esforço individual e da rede de contatos do dono. Funciona, mas é frágil.
A20: 02 · Estruturado | B20: Quanto você quer vender? | C20: Plano por fonte de receita, processos-chave definidos, cadência semanal de reunião e diagnóstico individual do time.
A21: 03 · Escalável | B21: Quais as principais ações para replicar as vendas de diferentes origens? | C21: Análise por canal, remuneração atrelada ao plano, playbooks por perfil e sistema integrado. A empresa opera vários silos de receita ao mesmo tempo.
A23: Um mesmo negócio pode estar em estágios diferentes em cada frente: a loja física madura e o digital ainda engatinhando. Reconhecer em que fase você está, em cada frente, é o primeiro passo.
